<robot name='mycar'>
    <!-- 通过添加一个footprint来避免机器人沉入地面 -->
    <link name="base_footprint">      
        <visual>
            <geometry>
                <box size="0.001 0.001 0.001"/>
            </geometry>
            <material name="car_color" >
                <color rgba='1 0 0 1'/>
            </material>
        </visual>
    </link> 

    <!-- 关联joint -->
    <joint name="link2footprint" type="fixed"> 
        <parent link='base_link'/>
        <child link='base_footprint'/>
        <origin xyz='0 0 -0.05' rpy='0 0 0' />
    </joint>

    <link name="base_link">      
        <visual>
            <geometry>
                <box size="0.3 0.2 0.1"/>
            </geometry>
            
            <origin xyz="0 0 0" rpy="0 0 0" />

            <material name="car_color" >
                <color rgba='0.5 0.2 0.1 0.5'/>
            </material>
        </visual>
    </link>    
    <!-- 摄像头 -->
    <link name="camera">      
        <visual>
            <geometry>
                <box size="0.03 0.05 0.05"/>
            </geometry>
            
            <origin xyz="0 0 0.025" rpy="0 0 0" />
            
            <material name="camera_color" >
                <color rgba='0.3 0.2 0.8 1'/>
            </material>
        </visual>
    </link>   
    
    <joint name="camera2base" type='continuous' >
        <parent link='base_link'/>
        <child link='camera'/>
        <origin xyz='0.12 0 0.05' rpy='0 0 0' />
        <!-- 关节旋转参考轴 -->
        <axis xyz='0 0 1'/>

    </joint>
</robot>